Workbook

Sheet curry
A1: Player | B1: Rk | C1: Gcar | D1: Gtm | E1: Date | F1: Team | H1: Opp | I1: Result | J1: GS | K1: MP | L1: FG | M1: FGA | N1: FG% | O1: 3P | P1: 3PA | Q1: 3P% | R1: 2P | S1: 2PA | T1: 2P% | U1: eFG% | V1: FT | W1: FTA | X1: FT% | Y1: ORB | Z1: DRB | AA1: TRB | AB1: AST | AC1: STL | AD1: BLK | AE1: TOV | AF1: PF | AG1: PTS | AH1: GmSc | AI1: +/-
A2: Steph Curry | B2: 1 | C2: 113 | D2: 1 | E2: 44667 | F2: GSW | H2: DEN | I2: W, 123-107 | K2: 0.90347222 | L2: 5 | M2: 13 | N2: 0.385 | O2: 3 | P2: 6 | Q2: 0.5 | R2: 2 | S2: 7 | T2: 0.286 | U2: 0.5 | V2: 3 | W2: 3 | X2: 1 | Y2: 2 | Z2: 1 | AA2: 3 | AB2: 4 | AC2: 1 | AD2: 0 | AE2: 1 | AF2: 1 | AG2: 16 | AH2: 13 | AI2: 17
A3: Steph Curry | B3: 2 | C3: 114 | D3: 2 | E3: 44669 | F3: GSW | H3: DEN | I3: W, 126-106 | K3: 0.95625 | L3: 12 | M3: 17 | N3: 0.706 | O3: 5 | P3: 10 | Q3: 0.5 | R3: 7 | S3: 7 | T3: 1 | U3: 0.853 | V3: 5 | W3: 7 | X3: 0.714 | Y3: 0 | Z3: 3 | AA3: 3 | AB3: 4 | AC3: 1 | AD3: 1 | AE3: 2 | AF3: 3 | AG3: 34 | AH3: 28.3 | AI3: 32
A4: Steph Curry | B4: 3 | C4: 115 | D4: 3 | E4: 44672 | F4: GSW | G4: @ | H4: DEN | I4: W, 118-113 | K4: 1.28125 | L4: 9 | M4: 17 | N4: 0.529 | O4: 3 | P4: 9 | Q4: 0.333 | R4: 6 | S4: 8 | T4: 0.75 | U4: 0.618 | V4: 6 | W4: 8 | X4: 0.75 | Y4: 0 | Z4: 3 | AA4: 3 | AB4: 6 | AC4: 0 | AD4: 0 | AE4: 4 | AF4: 3 | AG4: 27 | AH4: 17.8 | AI4: 3
A5: Steph Curry | B5: 4 | C5: 116 | D5: 4 | E5: 44675 | F5: GSW | G5: @ | H5: DEN | I5: L, 121-126 | K5: 1.5347222 | L5: 10 | M5: 23 | N5: 0.435 | O5: 3 | P5: 11 | Q5: 0.273 | R5: 7 | S5: 12 | T5: 0.583 | U5: 0.5 | V5: 10 | W5: 14 | X5: 0.714 | Y5: 0 | Z5: 3 | AA5: 3 | AB5: 8 | AC5: 4 | AD5: 1 | AE5: 2 | AF5: 1 | AG5: 33 | AH5: 28.1 | AI5: -4
A6: Steph Curry | B6: 5 | C6: 117 | D6: 5 | E6: 44678 | F6: GSW | H6: DEN | I6: W, 102-98 | J6: * | K6: 1.5770833 | L6: 10 | M6: 22 | N6: 0.455 | O6: 5 | P6: 11 | Q6: 0.455 | R6: 5 | S6: 11 | T6: 0.455 | U6: 0.568 | V6: 5 | W6: 7 | X6: 0.714 | Y6: 1 | Z6: 4 | AA6: 5 | AB6: 5 | AC6: 2 | AD6: 0 | AE6: 5 | AF6: 2 | AG6: 30 | AH6: 19.4 | AI6: 7
A7: Steph Curry | B7: 6 | C7: 118 | D7: 6 | E7: 44682 | F7: GSW | G7: @ | H7: MEM | I7: W, 117-116 | J7: * | K7: 1.5458333 | L7: 8 | M7: 20 | N7: 0.4 | O7: 5 | P7: 12 | Q7: 0.417 | R7: 3 | S7: 8 | T7: 0.375 | U7: 0.525 | V7: 3 | W7: 4 | X7: 0.75 | Y7: 0 | Z7: 3 | AA7: 3 | AB7: 4 | AC7: 0 | AD7: 1 | AE7: 1 | AF7: 5 | AG7: 24 | AH7: 14.2 | AI7: -9
A8: Steph Curry | B8: 7 | C8: 119 | D8: 7 | E8: 44684 | F8: GSW | G8: @ | H8: MEM | I8: L, 101-106 | J8: * | K8: 1.64375 | L8: 11 | M8: 25 | N8: 0.44 | O8: 3 | P8: 11 | Q8: 0.273 | R8: 8 | S8: 14 | T8: 0.571 | U8: 0.5 | V8: 2 | W8: 2 | X8: 1 | Y8: 3 | Z8: 6 | AA8: 9 | AB8: 8 | AC8: 1 | AD8: 0 | AE8: 5 | AF8: 1 | AG8: 27 | AH8: 19 | AI8: -11
A9: Steph Curry | B9: 8 | C9: 120 | D9: 8 | E9: 44688 | F9: GSW | H9: MEM | I9: W, 142-112 | J9: * | K9: 1.4458333 | L9: 7 | M9: 14 | N9: 0.5 | O9: 2 | P9: 8 | Q9: 0.25 | R9: 5 | S9: 6 | T9: 0.833 | U9: 0.571 | V9: 14 | W9: 14 | X9: 1 | Y9: 0 | Z9: 2 | AA9: 2 | AB9: 6 | AC9: 1 | AD9: 0 | AE9: 1 | AF9: 2 | AG9: 30 | AH9: 27 | AI9: 21
A10: Steph Curry | B10: 9 | C10: 121 | D10: 9 | E10: 44690 | F10: GSW | H10: MEM | I10: W, 101-98 | J10: * | K10: 1.5708333 | L10: 10 | M10: 25 | N10: 0.4 | O10: 4 | P10: 14 | Q10: 0.286 | R10: 6 | S10: 11 | T10: 0.545 | U10: 0.48 | V10: 8 | W10: 9 | X10: 0.889 | Y10: 0 | Z10: 5 | AA10: 5 | AB10: 8 | AC10: 1 | AD10: 0 | AE10: 3 | AF10: 3 | AG10: 32 | AH10: 22 | AI10: 6
A11: Steph Curry | B11: 10 | C11: 122 | D11: 10 | E11: 44692 | F11: GSW | G11: @ | H11: MEM | I11: L, 95-134 | J11: * | K11: 1.0416667 | L11: 4 | M11: 10 | N11: 0.4 | O11: 3 | P11: 8 | Q11: 0.375 | R11: 1 | S11: 2 | T11: 0.5 | U11: 0.55 | V11: 3 | W11: 4 | X11: 0.75 | Y11: 0 | Z11: 3 | AA11: 3 | AB11: 4 | AC11: 0 | AD11: 0 | AE11: 2 | AF11: 1 | AG11: 14 | AH11: 9.5 | AI11: -37
A12: Steph Curry | B12: 11 | C12: 123 | D12: 11 | E12: 44694 | F12: GSW | H12: MEM | I12: W, 110-96 | J12: * | K12: 1.675 | L12: 10 | M12: 27 | N12: 0.37 | O12: 6 | P12: 17 | Q12: 0.353 | R12: 4 | S12: 10 | T12: 0.4 | U12: 0.481 | V12: 3 | W12: 4 | X12: 0.75 | Y12: 0 | Z12: 7 | AA12: 7 | AB12: 5 | AC12: 1 | AD12: 2 | AE12: 3 | AF12: 3 | AG12: 29 | AH12: 17.5 | AI12: 16
A13: Steph Curry | B13: 12 | C13: 124 | D13: 12 | E13: 44699 | F13: GSW | H13: DAL | I13: W, 112-87 | J13: * | K13: 1.2805556 | L13: 7 | M13: 16 | N13: 0.438 | O13: 3 | P13: 9 | Q13: 0.333 | R13: 4 | S13: 7 | T13: 0.571 | U13: 0.531 | V13: 4 | W13: 7 | X13: 0.571 | Y13: 2 | Z13: 10 | AA13: 12 | AB13: 4 | AC13: 1 | AD13: 1 | AE13: 3 | AF13: 3 | AG13: 21 | AH13: 16.1 | AI13: 23
A14: Steph Curry | B14: 13 | C14: 125 | D14: 13 | E14: 44701 | F14: GSW | H14: DAL | I14: W, 126-117 | J14: * | K14: 1.5423611 | L14: 11 | M14: 21 | N14: 0.524 | O14: 6 | P14: 10 | Q14: 0.6 | R14: 5 | S14: 11 | T14: 0.455 | U14: 0.667 | V14: 4 | W14: 4 | X14: 1 | Y14: 0 | Z14: 8 | AA14: 8 | AB14: 5 | AC14: 0 | AD14: 0 | AE14: 3 | AF14: 4 | AG14: 32 | AH14: 23 | AI14: 15
A15: Steph Curry | B15: 14 | C15: 126 | D15: 14 | E15: 44703 | F15: GSW | G15: @ | H15: DAL | I15: W, 109-100 | J15: * | K15: 1.6256944 | L15: 10 | M15: 20 | N15: 0.5 | O15: 5 | P15: 10 | Q15: 0.5 | R15: 5 | S15: 10 | T15: 0.5 | U15: 0.625 | V15: 6 | W15: 6 | X15: 1 | Y15: 1 | Z15: 4 | AA15: 5 | AB15: 11 | AC15: 0 | AD15: 0 | AE15: 3 | AF15: 5 | AG15: 31 | AH15: 25.6 | AI15: 19
A16: Steph Curry | B16: 15 | C16: 127 | D16: 15 | E16: 44705 | F16: GSW | G16: @ | H16: DAL | I16: L, 109-119 | J16: * | K16: 1.3569444 | L16: 7 | M16: 16 | N16: 0.438 | O16: 2 | P16: 5 | Q16: 0.4 | R16: 5 | S16: 11 | T16: 0.455 | U16: 0.5 | V16: 4 | W16: 5 | X16: 0.8 | Y16: 0 | Z16: 5 | AA16: 5 | AB16: 8 | AC16: 1 | AD16: 0 | AE16: 2 | AF16: 2 | AG16: 20 | AH16: 16.5 | AI16: -23
A17: Steph Curry | B17: 16 | C17: 128 | D17: 16 | E17: 44707 | F17: GSW | H17: DAL | I17: W, 120-110 | J17: * | K17: 1.4513889 | L17: 5 | M17: 17 | N17: 0.294 | O17: 2 | P17: 7 | Q17: 0.286 | R17: 3 | S17: 10 | T17: 0.3 | U17: 0.353 | V17: 3 | W17: 3 | X17: 1 | Y17: 0 | Z17: 3 | AA17: 3 | AB17: 9 | AC17: 3 | AD17: 1 | AE17: 2 | AF17: 2 | AG17: 15 | AH17: 13.2 | AI17: 11
A18: Steph Curry | B18: 17 | C18: 129 | D18: 17 | E18: 44714 | F18: GSW | H18: BOS | I18: L, 108-120 | J18: * | K18: 1.5951389 | L18: 12 | M18: 25 | N18: 0.48 | O18: 7 | P18: 14 | Q18: 0.5 | R18: 5 | S18: 11 | T18: 0.455 | U18: 0.62 | V18: 3 | W18: 4 | X18: 0.75 | Y18: 0 | Z18: 5 | AA18: 5 | AB18: 5 | AC18: 3 | AD18: 0 | AE18: 2 | AF18: 3 | AG18: 34 | AH18: 25.7 | AI18: -9
A19: Steph Curry | B19: 18 | C19: 130 | D19: 18 | E19: 44717 | F19: GSW | H19: BOS | I19: W, 107-88 | J19: * | K19: 1.3409722 | L19: 9 | M19: 21 | N19: 0.429 | O19: 5 | P19: 12 | Q19: 0.417 | R19: 4 | S19: 9 | T19: 0.444 | U19: 0.548 | V19: 6 | W19: 7 | X19: 0.857 | Y19: 0 | Z19: 6 | AA19: 6 | AB19: 4 | AC19: 3 | AD19: 0 | AE19: 2 | AF19: 2 | AG19: 29 | AH19: 22.3 | AI19: 24
A20: Steph Curry | B20: 19 | C20: 131 | D20: 19 | E20: 44720 | F20: GSW | G20: @ | H20: BOS | I20: L, 100-116 | J20: * | K20: 1.5472222 | L20: 12 | M20: 22 | N20: 0.545 | O20: 6 | P20: 11 | Q20: 0.545 | R20: 6 | S20: 11 | T20: 0.545 | U20: 0.682 | V20: 1 | W20: 1 | X20: 1 | Y20: 0 | Z20: 4 | AA20: 4 | AB20: 2 | AC20: 2 | AD20: 0 | AE20: 3 | AF20: 4 | AG20: 31 | AH20: 20.4 | AI20: -14
A21: Steph Curry | B21: 20 | C21: 132 | D21: 20 | E21: 44722 | F21: GSW | G21: @ | H21: BOS | I21: W, 107-97 | J21: * | K21: 1.6951389 | L21: 14 | M21: 26 | N21: 0.538 | O21: 7 | P21: 14 | Q21: 0.5 | R21: 7 | S21: 12 | T21: 0.583 | U21: 0.673 | V21: 8 | W21: 9 | X21: 0.889 | Y21: 2 | Z21: 8 | AA21: 10 | AB21: 4 | AC21: 0 | AD21: 0 | AE21: 5 | AF21: 3 | AG21: 43 | AH21: 30.4 | AI21: 11
A22: Steph Curry | B22: 21 | C22: 133 | D22: 21 | E22: 44725 | F22: GSW | H22: BOS | I22: W, 104-94 | J22: * | K22: 1.5472222 | L22: 7 | M22: 22 | N22: 0.318 | O22: 0 | P22: 9 | Q22: 0 | R22: 7 | S22: 13 | T22: 0.538 | U22: 0.318 | V22: 2 | W22: 3 | X22: 0.667 | Y22: 0 | Z22: 4 | AA22: 4 | AB22: 8 | AC22: 2 | AD22: 0 | AE22: 1 | AF22: 2 | AG22: 16 | AH22: 10 | AI22: 15
A23: Steph Curry | B23: 22 | C23: 134 | D23: 22 | E23: 44728 | F23: GSW | G23: @ | H23: BOS | I23: W, 103-90 | J23: * | K23: 1.6638889 | L23: 12 | M23: 21 | N23: 0.571 | O23: 6 | P23: 11 | Q23: 0.545 | R23: 6 | S23: 10 | T23: 0.6 | U23: 0.714 | V23: 4 | W23: 4 | X23: 1 | Y23: 0 | Z23: 7 | AA23: 7 | AB23: 7 | AC23: 2 | AD23: 1 | AE23: 2 | AF23: 4 | AG23: 34 | AH23: 30.2 | AI23: 8
A24: Steph Curry | B24: 1 | C24: 763 | D24: 1 | E24: 44488 | F24: GSW | G24: @ | H24: LAL | I24: W 121-114 | J24: * | K24: 1.5076389 | L24: 5 | M24: 21 | N24: 0.238 | O24: 2 | P24: 8 | Q24: 0.25 | R24: 3 | S24: 13 | T24: 0.231 | U24: 0.286 | V24: 9 | W24: 9 | X24: 1 | Y24: 1 | Z24: 9 | AA24: 10 | AB24: 10 | AC24: 3 | AD24: 0 | AE24: 4 | AF24: 1 | AG24: 21 | AH24: 17.3 | AI24: 4
A25: Steph Curry | B25: 2 | C25: 764 | D25: 2 | E25: 44490 | F25: GSW | H25: LAC | I25: W 115-113 | J25: * | K25: 1.5645833 | L25: 16 | M25: 25 | N25: 0.64 | O25: 8 | P25: 13 | Q25: 0.615 | R25: 8 | S25: 12 | T25: 0.667 | U25: 0.8 | V25: 5 | W25: 5 | X25: 1 | Y25: 0 | Z25: 10 | AA25: 10 | AB25: 1 | AC25: 1 | AD25: 1 | AE25: 6 | AF25: 2 | AG25: 45 | AH25: 32.5 | AI25: -2
A26: Steph Curry | B26: 3 | C26: 765 | D26: 3 | E26: 44493 | F26: GSW | G26: @ | H26: SAC | I26: W 119-107 | J26: * | K26: 1.4694444 | L26: 9 | M26: 23 | N26: 0.391 | O26: 4 | P26: 15 | Q26: 0.267 | R26: 5 | S26: 8 | T26: 0.625 | U26: 0.478 | V26: 5 | W26: 6 | X26: 0.833 | Y26: 1 | Z26: 6 | AA26: 7 | AB26: 10 | AC26: 3 | AD26: 0 | AE26: 3 | AF26: 1 | AG26: 27 | AH26: 23.2 | AI26: 14
A27: Steph Curry | B27: 4 | C27: 766 | D27: 4 | E27: 44495 | F27: GSW | G27: @ | H27: OKC | I27: W 106-98 | J27: * | K27: 1.3458333 | L27: 6 | M27: 14 | N27: 0.429 | O27: 4 | P27: 9 | Q27: 0.444 | R27: 2 | S27: 5 | T27: 0.4 | U27: 0.571 | V27: 7 | W27: 7 | X27: 1 | Y27: 1 | Z27: 5 | AA27: 6 | AB27: 4 | AC27: 0 | AD27: 1 | AE27: 4 | AF27: 1 | AG27: 23 | AH27: 16.9 | AI27: 15
A28: Steph Curry | B28: 5 | C28: 767 | D28: 5 | E28: 44497 | F28: GSW | H28: MEM | I28: L 101-104 (OT) | J28: * | K28: 1.6944444 | L28: 11 | M28: 29 | N28: 0.379 | O28: 7 | P28: 20 | Q28: 0.35 | R28: 4 | S28: 9 | T28: 0.444 | U28: 0.5 | V28: 7 | W28: 7 | X28: 1 | Y28: 1 | Z28: 6 | AA28: 7 | AB28: 8 | AC28: 1 | AD28: 0 | AE28: 5 | AF28: 2 | AG28: 36 | AH28: 23.4 | AI28: 12
A29: Steph Curry | B29: 6 | C29: 768 | D29: 6 | E29: 44499 | F29: GSW | H29: OKC | I29: W 103-82 | J29: * | K29: 1.1326389 | L29: 7 | M29: 16 | N29: 0.438 | O29: 6 | P29: 15 | Q29: 0.4 | R29: 1 | S29: 1 | T29: 1 | U29: 0.625 | V29: 0 | W29: 0 | Y29: 0 | Z29: 5 | AA29: 5 | AB29: 6 | AC29: 1 | AD29: 1 | AE29: 2 | AF29: 1 | AG29: 20 | AH29: 16.6 | AI29: 17
A30: Steph Curry | B30: 7 | C30: 769 | D30: 7 | E30: 44503 | F30: GSW | H30: CHO | I30: W 114-92 | J30: * | K30: 1.4756944 | L30: 6 | M30: 15 | N30: 0.4 | O30: 3 | P30: 11 | Q30: 0.273 | R30: 3 | S30: 4 | T30: 0.75 | U30: 0.5 | V30: 0 | W30: 0 | Y30: 1 | Z30: 7 | AA30: 8 | AB30: 9 | AC30: 1 | AD30: 1 | AE30: 4 | AF30: 3 | AG30: 15 | AH30: 12.5 | AI30: -1
A31: Steph Curry | B31: 8 | C31: 770 | D31: 8 | E31: 44505 | F31: GSW | H31: NOP | I31: W 126-85 | J31: * | K31: 1.2395833 | L31: 5 | M31: 16 | N31: 0.313 | O31: 5 | P31: 13 | Q31: 0.385 | R31: 0 | S31: 3 | T31: 0 | U31: 0.469 | V31: 4 | W31: 4 | X31: 1 | Y31: 0 | Z31: 3 | AA31: 3 | AB31: 6 | AC31: 0 | AD31: 2 | AE31: 1 | AF31: 1 | AG31: 19 | AH31: 14.9 | AI31: 17
A32: Steph Curry | B32: 9 | C32: 771 | D32: 9 | E32: 44507 | F32: GSW | H32: HOU | I32: W 120-107 | J32: * | K32: 1.1173611 | L32: 8 | M32: 16 | N32: 0.5 | O32: 4 | P32: 11 | Q32: 0.364 | R32: 4 | S32: 5 | T32: 0.8 | U32: 0.625 | V32: 0 | W32: 0 | Y32: 2 | Z32: 1 | AA32: 3 | AB32: 2 | AC32: 3 | AD32: 0 | AE32: 0 | AF32: 3 | AG32: 20 | AH32: 16.9 | AI32: 16
A33: Steph Curry | B33: 10 | C33: 772 | D33: 10 | E33: 44508 | F33: GSW | H33: ATL | I33: W 127-113 | J33: * | K33: 1.4597222 | L33: 14 | M33: 28 | N33: 0.5 | O33: 9 | P33: 19 | Q33: 0.474 | R33: 5 | S33: 9 | T33: 0.556 | U33: 0.661 | V33: 13 | W33: 13 | X33: 1 | Y33: 2 | Z33: 5 | AA33: 7 | AB33: 10 | AC33: 4 | AD33: 1 | AE33: 2 | AF33: 0 | AG33: 50 | AH33: 48.6 | AI33: 31
A34: Steph Curry | B34: 11 | C34: 773 | D34: 11 | E34: 44510 | F34: GSW | H34: MIN | I34: W 123-110 | J34: * | K34: 1.4208333 | L34: 8 | M34: 16 | N34: 0.5 | O34: 3 | P34: 9 | Q34: 0.333 | R34: 5 | S34: 7 | T34: 0.714 | U34: 0.594 | V34: 6 | W34: 8 | X34: 0.75 | Y34: 0 | Z34: 5 | AA34: 5 | AB34: 6 | AC34: 1 | AD34: 0 | AE34: 3 | AF34: 2 | AG34: 25 | AH34: 19.1 | AI34: 11
A35: Steph Curry | B35: 12 | C35: 774 | D35: 12 | E35: 44512 | F35: GSW | H35: CHI | I35: W 119-93 | J35: * | K35: 1.4256944 | L35: 15 | M35: 24 | N35: 0.625 | O35: 9 | P35: 17 | Q35: 0.529 | R35: 6 | S35: 7 | T35: 0.857 | U35: 0.813 | V35: 1 | W35: 1 | X35: 1 | Y35: 0 | Z35: 4 | AA35: 4 | AB35: 5 | AC35: 1 | AD35: 1 | AE35: 6 | AF35: 1 | AG35: 40 | AH35: 29.2 | AI35: 31
A36: Steph Curry | B36: 13 | C36: 775 | D36: 13 | E36: 44514 | F36: GSW | G36: @ | H36: CHO | I36: L 102-106 | J36: * | K36: 1.4875 | L36: 7 | M36: 22 | N36: 0.318 | O36: 3 | P36: 13 | Q36: 0.231 | R36: 4 | S36: 9 | T36: 0.444 | U36: 0.386 | V36: 7 | W36: 7 | X36: 1 | Y36: 1 | Z36: 5 | AA36: 6 | AB36: 10 | AC36: 3 | AD36: 1 | AE36: 3 | AF36: 2 | AG36: 24 | AH36: 20.5 | AI36: 14
A37: Steph Curry | B37: 14 | C37: 776 | D37: 14 | E37: 44516 | F37: GSW | G37: @ | H37: BRK | I37: W 117-99 | J37: * | K37: 1.21875 | L37: 12 | M37: 19 | N37: 0.632 | O37: 9 | P37: 14 | Q37: 0.643 | R37: 3 | S37: 5 | T37: 0.6 | U37: 0.868 | V37: 4 | W37: 4 | X37: 1 | Y37: 0 | Z37: 7 | AA37: 7 | AB37: 5 | AC37: 2 | AD37: 1 | AE37: 2 | AF37: 4 | AG37: 37 | AH37: 33.2 | AI37: 16
A38: Steph Curry | B38: 15 | C38: 777 | D38: 15 | E38: 44518 | F38: GSW | G38: @ | H38: CLE | I38: W 104-89 | J38: * | K38: 1.4743056 | L38: 15 | M38: 27 | N38: 0.556 | O38: 9 | P38: 16 | Q38: 0.563 | R38: 6 | S38: 11 | T38: 0.545 | U38: 0.722 | V38: 1 | W38: 1 | X38: 1 | Y38: 0 | Z38: 4 | AA38: 4 | AB38: 6 | AC38: 2 | AD38: 0 | AE38: 3 | AF38: 4 | AG38: 40 | AH38: 29.9 | AI38: 8
A39: Steph Curry | B39: 15 | D39: 16 | E39: 44519 | F39: GSW | G39: @ | H39: DET | I39: W 105-102 | J39: Inactive | K39: Inactive | L39: Inactive | M39: Inactive | N39: Inactive | O39: Inactive | P39: Inactive | Q39: Inactive | R39: Inactive | S39: Inactive | T39: Inactive | U39: Inactive | V39: Inactive | W39: Inactive | X39: Inactive | Y39: Inactive | Z39: Inactive | AA39: Inactive | AB39: Inactive | AC39: Inactive | AD39: Inactive | AE39: Inactive | AF39: Inactive | AG39: Inactive | AH39: Inactive | AI39: Inactive
A40: Steph Curry | B40: 16 | C40: 778 | D40: 17 | E40: 44521 | F40: GSW | H40: TOR | I40: W 119-104 | J40: * | K40: 1.5444444 | L40: 2 | M40: 10 | N40: 0.2 | O40: 1 | P40: 6 | Q40: 0.167 | R40: 1 | S40: 4 | T40: 0.25 | U40: 0.25 | V40: 7 | W40: 7 | X40: 1 | Y40: 0 | Z40: 2 | AA40: 2 | AB40: 8 | AC40: 1 | AD40: 0 | AE40: 4 | AF40: 1 | AG40: 12 | AH40: 8.6 | AI40: 19
...

Sheet wiggins
A1: Player | B1: Rk | C1: Gcar | D1: Gtm | E1: Date | F1: Team | H1: Opp | I1: Result | J1: GS | K1: MP | L1: FG | M1: FGA | N1: FG% | O1: 3P | P1: 3PA | Q1: 3P% | R1: 2P | S1: 2PA | T1: 2P% | U1: eFG% | V1: FT | W1: FTA | X1: FT% | Y1: ORB | Z1: DRB | AA1: TRB | AB1: AST | AC1: STL | AD1: BLK | AE1: TOV | AF1: PF | AG1: PTS | AH1: GmSc | AI1: +/-
A2: Andrew Wiggins | B2: 1 | C2: 526 | D2: 1 | E2: 44488 | F2: GSW | G2: @ | H2: LAL | I2: W 121-114 | J2: * | K2: 1.0722222 | L2: 5 | M2: 10 | N2: 0.5 | O2: 2 | P2: 5 | Q2: 0.4 | R2: 3 | S2: 5 | T2: 0.6 | U2: 0.6 | V2: 0 | W2: 0 | Y2: 1 | Z2: 6 | AA2: 7 | AB2: 1 | AC2: 1 | AD2: 0 | AE2: 2 | AF2: 3 | AG2: 12 | AH2: 8 | AI2: -5
A3: Andrew Wiggins | B3: 2 | C3: 527 | D3: 2 | E3: 44490 | F3: GSW | H3: LAC | I3: W 115-113 | J3: * | K3: 1.28125 | L3: 6 | M3: 15 | N3: 0.4 | O3: 3 | P3: 6 | Q3: 0.5 | R3: 3 | S3: 9 | T3: 0.333 | U3: 0.5 | V3: 2 | W3: 2 | X3: 1 | Y3: 3 | Z3: 3 | AA3: 6 | AB3: 3 | AC3: 1 | AD3: 1 | AE3: 2 | AF3: 1 | AG3: 17 | AH3: 13.3 | AI3: -5
A4: Andrew Wiggins | B4: 3 | C4: 528 | D4: 3 | E4: 44493 | F4: GSW | G4: @ | H4: SAC | I4: W 119-107 | J4: * | K4: 1.3 | L4: 6 | M4: 13 | N4: 0.462 | O4: 2 | P4: 5 | Q4: 0.4 | R4: 4 | S4: 8 | T4: 0.5 | U4: 0.538 | V4: 3 | W4: 4 | X4: 0.75 | Y4: 2 | Z4: 2 | AA4: 4 | AB4: 0 | AC4: 0 | AD4: 0 | AE4: 0 | AF4: 1 | AG4: 17 | AH4: 11.5 | AI4: 18
A5: Andrew Wiggins | B5: 4 | C5: 529 | D5: 4 | E5: 44495 | F5: GSW | G5: @ | H5: OKC | I5: W 106-98 | J5: * | K5: 1.2791667 | L5: 9 | M5: 17 | N5: 0.529 | O5: 0 | P5: 5 | Q5: 0 | R5: 9 | S5: 12 | T5: 0.75 | U5: 0.529 | V5: 3 | W5: 5 | X5: 0.6 | Y5: 1 | Z5: 3 | AA5: 4 | AB5: 4 | AC5: 3 | AD5: 1 | AE5: 2 | AF5: 0 | AG5: 21 | AH5: 18 | AI5: 4
A6: Andrew Wiggins | B6: 5 | C6: 530 | D6: 5 | E6: 44497 | F6: GSW | H6: MEM | I6: L 101-104 (OT) | J6: * | K6: 1.5583333 | L6: 7 | M6: 15 | N6: 0.467 | O6: 1 | P6: 4 | Q6: 0.25 | R6: 6 | S6: 11 | T6: 0.545 | U6: 0.5 | V6: 1 | W6: 2 | X6: 0.5 | Y6: 0 | Z6: 4 | AA6: 4 | AB6: 1 | AC6: 1 | AD6: 1 | AE6: 2 | AF6: 1 | AG6: 16 | AH6: 9.1 | AI6: 0
A7: Andrew Wiggins | B7: 6 | C7: 531 | D7: 6 | E7: 44499 | F7: GSW | H7: OKC | I7: W 103-82 | J7: * | K7: 1.0347222 | L7: 5 | M7: 13 | N7: 0.385 | O7: 4 | P7: 5 | Q7: 0.8 | R7: 1 | S7: 8 | T7: 0.125 | U7: 0.538 | V7: 0 | W7: 0 | Y7: 2 | Z7: 0 | AA7: 2 | AB7: 1 | AC7: 1 | AD7: 0 | AE7: 0 | AF7: 1 | AG7: 14 | AH7: 9.6 | AI7: 17
A8: Andrew Wiggins | B8: 7 | C8: 532 | D8: 7 | E8: 44503 | F8: GSW | H8: CHO | I8: W 114-92 | J8: * | K8: 1.1979167 | L8: 4 | M8: 12 | N8: 0.333 | O8: 2 | P8: 6 | Q8: 0.333 | R8: 2 | S8: 6 | T8: 0.333 | U8: 0.417 | V8: 4 | W8: 4 | X8: 1 | Y8: 1 | Z8: 5 | AA8: 6 | AB8: 3 | AC8: 0 | AD8: 0 | AE8: 1 | AF8: 3 | AG8: 14 | AH8: 9.3 | AI8: 9
A9: Andrew Wiggins | B9: 8 | C9: 533 | D9: 8 | E9: 44505 | F9: GSW | H9: NOP | I9: W 126-85 | J9: * | K9: 1.0902778 | L9: 6 | M9: 13 | N9: 0.462 | O9: 1 | P9: 5 | Q9: 0.2 | R9: 5 | S9: 8 | T9: 0.625 | U9: 0.5 | V9: 3 | W9: 4 | X9: 0.75 | Y9: 0 | Z9: 3 | AA9: 3 | AB9: 0 | AC9: 0 | AD9: 0 | AE9: 1 | AF9: 2 | AG9: 16 | AH9: 8 | AI9: 8
A10: Andrew Wiggins | B10: 9 | C10: 534 | D10: 9 | E10: 44507 | F10: GSW | H10: HOU | I10: W 120-107 | J10: * | K10: 1.2416667 | L10: 4 | M10: 11 | N10: 0.364 | O10: 1 | P10: 6 | Q10: 0.167 | R10: 3 | S10: 5 | T10: 0.6 | U10: 0.409 | V10: 7 | W10: 8 | X10: 0.875 | Y10: 1 | Z10: 2 | AA10: 3 | AB10: 2 | AC10: 0 | AD10: 0 | AE10: 3 | AF10: 3 | AG10: 16 | AH10: 8 | AI10: 5
A11: Andrew Wiggins | B11: 10 | C11: 535 | D11: 10 | E11: 44508 | F11: GSW | H11: ATL | I11: W 127-113 | J11: * | K11: 1.0840278 | L11: 5 | M11: 12 | N11: 0.417 | O11: 1 | P11: 4 | Q11: 0.25 | R11: 4 | S11: 8 | T11: 0.5 | U11: 0.458 | V11: 2 | W11: 2 | X11: 1 | Y11: 1 | Z11: 3 | AA11: 4 | AB11: 1 | AC11: 1 | AD11: 0 | AE11: 1 | AF11: 0 | AG11: 13 | AH11: 8.9 | AI11: 3
A12: Andrew Wiggins | B12: 11 | C12: 536 | D12: 11 | E12: 44510 | F12: GSW | H12: MIN | I12: W 123-110 | J12: * | K12: 1.3215278 | L12: 14 | M12: 19 | N12: 0.737 | O12: 3 | P12: 6 | Q12: 0.5 | R12: 11 | S12: 13 | T12: 0.846 | U12: 0.816 | V12: 4 | W12: 4 | X12: 1 | Y12: 1 | Z12: 3 | AA12: 4 | AB12: 0 | AC12: 2 | AD12: 0 | AE12: 4 | AF12: 3 | AG12: 35 | AH12: 25.7 | AI12: 6
A13: Andrew Wiggins | B13: 12 | C13: 537 | D13: 12 | E13: 44512 | F13: GSW | H13: CHI | I13: W 119-93 | J13: * | K13: 1.2222222 | L13: 5 | M13: 15 | N13: 0.333 | O13: 0 | P13: 4 | Q13: 0 | R13: 5 | S13: 11 | T13: 0.455 | U13: 0.333 | V13: 5 | W13: 7 | X13: 0.714 | Y13: 3 | Z13: 4 | AA13: 7 | AB13: 2 | AC13: 2 | AD13: 1 | AE13: 1 | AF13: 1 | AG13: 15 | AH13: 11.7 | AI13: 13
A14: Andrew Wiggins | B14: 13 | C14: 538 | D14: 13 | E14: 44514 | F14: GSW | G14: @ | H14: CHO | I14: L 102-106 | J14: * | K14: 1.3402778 | L14: 12 | M14: 19 | N14: 0.632 | O14: 3 | P14: 7 | Q14: 0.429 | R14: 9 | S14: 12 | T14: 0.75 | U14: 0.711 | V14: 1 | W14: 3 | X14: 0.333 | Y14: 0 | Z14: 6 | AA14: 6 | AB14: 2 | AC14: 0 | AD14: 0 | AE14: 0 | AF14: 1 | AG14: 28 | AH14: 21.5 | AI14: -4
A15: Andrew Wiggins | B15: 14 | C15: 539 | D15: 14 | E15: 44516 | F15: GSW | G15: @ | H15: BRK | I15: W 117-99 | J15: * | K15: 0.92222222 | L15: 7 | M15: 11 | N15: 0.636 | O15: 2 | P15: 3 | Q15: 0.667 | R15: 5 | S15: 8 | T15: 0.625 | U15: 0.727 | V15: 3 | W15: 3 | X15: 1 | Y15: 0 | Z15: 2 | AA15: 2 | AB15: 1 | AC15: 0 | AD15: 1 | AE15: 3 | AF15: 4 | AG15: 19 | AH15: 11.5 | AI15: 10
A16: Andrew Wiggins | B16: 15 | C16: 540 | D16: 15 | E16: 44518 | F16: GSW | G16: @ | H16: CLE | I16: W 104-89 | J16: * | K16: 1.00625 | L16: 5 | M16: 11 | N16: 0.455 | O16: 0 | P16: 5 | Q16: 0 | R16: 5 | S16: 6 | T16: 0.833 | U16: 0.455 | V16: 2 | W16: 2 | X16: 1 | Y16: 0 | Z16: 0 | AA16: 0 | AB16: 2 | AC16: 0 | AD16: 1 | AE16: 3 | AF16: 1 | AG16: 12 | AH16: 5 | AI16: -14
A17: Andrew Wiggins | B17: 16 | C17: 541 | D17: 16 | E17: 44519 | F17: GSW | G17: @ | H17: DET | I17: W 105-102 | J17: * | K17: 1.5215278 | L17: 9 | M17: 19 | N17: 0.474 | O17: 1 | P17: 4 | Q17: 0.25 | R17: 8 | S17: 15 | T17: 0.533 | U17: 0.5 | V17: 8 | W17: 11 | X17: 0.727 | Y17: 1 | Z17: 4 | AA17: 5 | AB17: 1 | AC17: 2 | AD17: 1 | AE17: 4 | AF17: 1 | AG17: 27 | AH17: 17 | AI17: 6
A18: Andrew Wiggins | B18: 17 | C18: 542 | D18: 17 | E18: 44521 | F18: GSW | H18: TOR | I18: W 119-104 | J18: * | K18: 1.3618056 | L18: 12 | M18: 20 | N18: 0.6 | O18: 6 | P18: 8 | Q18: 0.75 | R18: 6 | S18: 12 | T18: 0.5 | U18: 0.75 | V18: 2 | W18: 2 | X18: 1 | Y18: 2 | Z18: 4 | AA18: 6 | AB18: 3 | AC18: 0 | AD18: 1 | AE18: 2 | AF18: 1 | AG18: 32 | AH18: 25.8 | AI18: 30
A19: Andrew Wiggins | B19: 18 | C19: 543 | D19: 18 | E19: 44524 | F19: GSW | H19: PHI | I19: W 116-96 | J19: * | K19: 1.4069444 | L19: 7 | M19: 13 | N19: 0.538 | O19: 2 | P19: 6 | Q19: 0.333 | R19: 5 | S19: 7 | T19: 0.714 | U19: 0.615 | V19: 3 | W19: 7 | X19: 0.429 | Y19: 0 | Z19: 6 | AA19: 6 | AB19: 1 | AC19: 1 | AD19: 1 | AE19: 1 | AF19: 0 | AG19: 19 | AH19: 14.3 | AI19: 25
A20: Andrew Wiggins | B20: 19 | C20: 544 | D20: 19 | E20: 44526 | F20: GSW | H20: POR | I20: W 118-103 | J20: * | K20: 1.4166667 | L20: 10 | M20: 16 | N20: 0.625 | O20: 3 | P20: 5 | Q20: 0.6 | R20: 7 | S20: 11 | T20: 0.636 | U20: 0.719 | V20: 2 | W20: 2 | X20: 1 | Y20: 2 | Z20: 3 | AA20: 5 | AB20: 2 | AC20: 1 | AD20: 0 | AE20: 1 | AF20: 3 | AG20: 25 | AH20: 20.3 | AI20: 21
A21: Andrew Wiggins | B21: 20 | C21: 545 | D21: 20 | E21: 44528 | F21: GSW | G21: @ | H21: LAC | I21: W 105-90 | J21: * | K21: 1.5048611 | L21: 4 | M21: 12 | N21: 0.333 | O21: 2 | P21: 5 | Q21: 0.4 | R21: 2 | S21: 7 | T21: 0.286 | U21: 0.417 | V21: 2 | W21: 6 | X21: 0.333 | Y21: 2 | Z21: 5 | AA21: 7 | AB21: 2 | AC21: 1 | AD21: 2 | AE21: 2 | AF21: 1 | AG21: 12 | AH21: 7.9 | AI21: 8
A22: Andrew Wiggins | B22: 21 | C22: 546 | D22: 21 | E22: 44530 | F22: GSW | G22: @ | H22: PHO | I22: L 96-104 | J22: * | K22: 1.3868056 | L22: 4 | M22: 12 | N22: 0.333 | O22: 0 | P22: 1 | Q22: 0 | R22: 4 | S22: 11 | T22: 0.364 | U22: 0.333 | V22: 2 | W22: 3 | X22: 0.667 | Y22: 1 | Z22: 2 | AA22: 3 | AB22: 2 | AC22: 1 | AD22: 1 | AE22: 1 | AF22: 2 | AG22: 10 | AH22: 5.4 | AI22: -7
A23: Andrew Wiggins | B23: 22 | C23: 547 | D23: 22 | E23: 44533 | F23: GSW | H23: PHO | I23: W 118-96 | J23: * | K23: 1.2451389 | L23: 8 | M23: 16 | N23: 0.5 | O23: 3 | P23: 7 | Q23: 0.429 | R23: 5 | S23: 9 | T23: 0.556 | U23: 0.594 | V23: 0 | W23: 0 | Y23: 1 | Z23: 4 | AA23: 5 | AB23: 2 | AC23: 0 | AD23: 0 | AE23: 2 | AF23: 4 | AG23: 19 | AH23: 10.7 | AI23: 24
A24: Andrew Wiggins | B24: 23 | C24: 548 | D24: 23 | E24: 44534 | F24: GSW | H24: SAS | I24: L 107-112 | J24: * | K24: 1.2881944 | L24: 3 | M24: 9 | N24: 0.333 | O24: 2 | P24: 3 | Q24: 0.667 | R24: 1 | S24: 6 | T24: 0.167 | U24: 0.444 | V24: 3 | W24: 4 | X24: 0.75 | Y24: 2 | Z24: 2 | AA24: 4 | AB24: 1 | AC24: 0 | AD24: 1 | AE24: 1 | AF24: 0 | AG24: 11 | AH24: 7.9 | AI24: -23
A25: Andrew Wiggins | B25: 24 | C25: 549 | D25: 24 | E25: 44536 | F25: GSW | H25: ORL | I25: W 126-95 | J25: * | K25: 1.2479167 | L25: 9 | M25: 17 | N25: 0.529 | O25: 8 | P25: 10 | Q25: 0.8 | R25: 1 | S25: 7 | T25: 0.143 | U25: 0.765 | V25: 2 | W25: 4 | X25: 0.5 | Y25: 1 | Z25: 2 | AA25: 3 | AB25: 3 | AC25: 1 | AD25: 0 | AE25: 1 | AF25: 2 | AG25: 28 | AH25: 21.5 | AI25: 18
A26: Andrew Wiggins | B26: 25 | C26: 550 | D26: 25 | E26: 44538 | F26: GSW | H26: POR | I26: W 104-94 | J26: * | K26: 1.3673611 | L26: 4 | M26: 9 | N26: 0.444 | O26: 2 | P26: 5 | Q26: 0.4 | R26: 2 | S26: 4 | T26: 0.5 | U26: 0.556 | V26: 4 | W26: 4 | X26: 1 | Y26: 1 | Z26: 3 | AA26: 4 | AB26: 2 | AC26: 1 | AD26: 0 | AE26: 0 | AF26: 2 | AG26: 14 | AH26: 12.5 | AI26: 2
A27: Andrew Wiggins | B27: 26 | C27: 551 | D27: 26 | E27: 44541 | F27: GSW | G27: @ | H27: PHI | I27: L 93-102 | J27: * | K27: 1.5263889 | L27: 8 | M27: 14 | N27: 0.571 | O27: 3 | P27: 8 | Q27: 0.375 | R27: 5 | S27: 6 | T27: 0.833 | U27: 0.679 | V27: 1 | W27: 3 | X27: 0.333 | Y27: 1 | Z27: 3 | AA27: 4 | AB27: 4 | AC27: 1 | AD27: 1 | AE27: 2 | AF27: 2 | AG27: 20 | AH27: 15.9 | AI27: 4
A28: Andrew Wiggins | B28: 27 | C28: 552 | D28: 27 | E28: 44543 | F28: GSW | G28: @ | H28: IND | I28: W 102-100 | J28: * | K28: 1.4208333 | L28: 7 | M28: 15 | N28: 0.467 | O28: 0 | P28: 3 | Q28: 0 | R28: 7 | S28: 12 | T28: 0.583 | U28: 0.467 | V28: 1 | W28: 1 | X28: 1 | Y28: 2 | Z28: 3 | AA28: 5 | AB28: 1 | AC28: 1 | AD28: 3 | AE28: 2 | AF28: 4 | AG28: 15 | AH28: 9.8 | AI28: -6
A29: Andrew Wiggins | B29: 28 | C29: 553 | D29: 28 | E29: 44544 | F29: GSW | G29: @ | H29: NYK | I29: W 105-96 | J29: * | K29: 1.4034722 | L29: 6 | M29: 13 | N29: 0.462 | O29: 3 | P29: 6 | Q29: 0.5 | R29: 3 | S29: 7 | T29: 0.429 | U29: 0.577 | V29: 3 | W29: 6 | X29: 0.5 | Y29: 1 | Z29: 5 | AA29: 6 | AB29: 3 | AC29: 0 | AD29: 0 | AE29: 2 | AF29: 1 | AG29: 18 | AH29: 12 | AI29: 4
A30: Andrew Wiggins | B30: 29 | C30: 554 | D30: 29 | E30: 44547 | F30: GSW | G30: @ | H30: BOS | I30: W 111-107 | J30: * | K30: 1.5027778 | L30: 11 | M30: 20 | N30: 0.55 | O30: 5 | P30: 7 | Q30: 0.714 | R30: 6 | S30: 13 | T30: 0.462 | U30: 0.675 | V30: 0 | W30: 0 | Y30: 3 | Z30: 3 | AA30: 6 | AB30: 2 | AC30: 1 | AD30: 1 | AE30: 0 | AF30: 4 | AG30: 27 | AH30: 21.9 | AI30: 13
A31: Andrew Wiggins | B31: 29 | D31: 30 | E31: 44548 | F31: GSW | G31: @ | H31: TOR | I31: L 100-119 | J31: Not With Team | K31: Not With Team | L31: Not With Team | M31: Not With Team | N31: Not With Team | O31: Not With Team | P31: Not With Team | Q31: Not With Team | R31: Not With Team | S31: Not With Team | T31: Not With Team | U31: Not With Team | V31: Not With Team | W31: Not With Team | X31: Not With Team | Y31: Not With Team | Z31: Not With Team | AA31: Not With Team | AB31: Not With Team | AC31: Not With Team | AD31: Not With Team | AE31: Not With Team | AF31: Not With Team | AG31: Not With Team | AH31: Not With Team | AI31: Not With Team
A32: Andrew Wiggins | B32: 29 | D32: 31 | E32: 44550 | F32: GSW | H32: SAC | I32: W 113-98 | J32: Inactive | K32: Inactive | L32: Inactive | M32: Inactive | N32: Inactive | O32: Inactive | P32: Inactive | Q32: Inactive | R32: Inactive | S32: Inactive | T32: Inactive | U32: Inactive | V32: Inactive | W32: Inactive | X32: Inactive | Y32: Inactive | Z32: Inactive | AA32: Inactive | AB32: Inactive | AC32: Inactive | AD32: Inactive | AE32: Inactive | AF32: Inactive | AG32: Inactive | AH32: Inactive | AI32: Inactive
A33: Andrew Wiggins | B33: 29 | D33: 32 | E33: 44553 | F33: GSW | H33: MEM | I33: W 113-104 | J33: Inactive | K33: Inactive | L33: Inactive | M33: Inactive | N33: Inactive | O33: Inactive | P33: Inactive | Q33: Inactive | R33: Inactive | S33: Inactive | T33: Inactive | U33: Inactive | V33: Inactive | W33: Inactive | X33: Inactive | Y33: Inactive | Z33: Inactive | AA33: Inactive | AB33: Inactive | AC33: Inactive | AD33: Inactive | AE33: Inactive | AF33: Inactive | AG33: Inactive | AH33: Inactive | AI33: Inactive
A34: Andrew Wiggins | B34: 29 | D34: 33 | E34: 44555 | F34: GSW | G34: @ | H34: PHO | I34: W 116-107 | J34: Inactive | K34: Inactive | L34: Inactive | M34: Inactive | N34: Inactive | O34: Inactive | P34: Inactive | Q34: Inactive | R34: Inactive | S34: Inactive | T34: Inactive | U34: Inactive | V34: Inactive | W34: Inactive | X34: Inactive | Y34: Inactive | Z34: Inactive | AA34: Inactive | AB34: Inactive | AC34: Inactive | AD34: Inactive | AE34: Inactive | AF34: Inactive | AG34: Inactive | AH34: Inactive | AI34: Inactive
A35: Andrew Wiggins | B35: 30 | C35: 555 | D35: 34 | E35: 44558 | F35: GSW | H35: DEN | I35: L 86-89 | J35: * | K35: 1.3326389 | L35: 8 | M35: 20 | N35: 0.4 | O35: 3 | P35: 6 | Q35: 0.5 | R35: 5 | S35: 14 | T35: 0.357 | U35: 0.475 | V35: 2 | W35: 3 | X35: 0.667 | Y35: 3 | Z35: 5 | AA35: 8 | AB35: 1 | AC35: 2 | AD35: 1 | AE35: 2 | AF35: 2 | AG35: 21 | AH35: 14 | AI35: 1
A36: Andrew Wiggins | B36: 31 | C36: 556 | D36: 35 | E36: 44562 | F36: GSW | G36: @ | H36: UTA | I36: W 123-116 | J36: * | K36: 1.5875 | L36: 9 | M36: 19 | N36: 0.474 | O36: 4 | P36: 6 | Q36: 0.667 | R36: 5 | S36: 13 | T36: 0.385 | U36: 0.579 | V36: 3 | W36: 7 | X36: 0.429 | Y36: 0 | Z36: 0 | AA36: 0 | AB36: 4 | AC36: 2 | AD36: 0 | AE36: 3 | AF36: 1 | AG36: 25 | AH36: 15.1 | AI36: 4
A37: Andrew Wiggins | B37: 32 | C37: 557 | D37: 36 | E37: 44564 | F37: GSW | H37: MIA | I37: W 115-108 | J37: * | K37: 1.4215278 | L37: 8 | M37: 13 | N37: 0.615 | O37: 2 | P37: 4 | Q37: 0.5 | R37: 6 | S37: 9 | T37: 0.667 | U37: 0.692 | V37: 4 | W37: 4 | X37: 1 | Y37: 0 | Z37: 6 | AA37: 6 | AB37: 4 | AC37: 2 | AD37: 0 | AE37: 3 | AF37: 1 | AG37: 22 | AH37: 19.3 | AI37: 13
A38: Andrew Wiggins | B38: 33 | C38: 558 | D38: 37 | E38: 44566 | F38: GSW | G38: @ | H38: DAL | I38: L 82-99 | J38: * | K38: 1.3541667 | L38: 7 | M38: 13 | N38: 0.538 | O38: 2 | P38: 5 | Q38: 0.4 | R38: 5 | S38: 8 | T38: 0.625 | U38: 0.615 | V38: 1 | W38: 4 | X38: 0.25 | Y38: 2 | Z38: 1 | AA38: 3 | AB38: 2 | AC38: 2 | AD38: 1 | AE38: 0 | AF38: 1 | AG38: 17 | AH38: 14.9 | AI38: -9
A39: Andrew Wiggins | B39: 34 | C39: 559 | D39: 38 | E39: 44567 | F39: GSW | G39: @ | H39: NOP | I39: L 96-101 | J39: * | K39: 1.3305556 | L39: 7 | M39: 17 | N39: 0.412 | O39: 1 | P39: 6 | Q39: 0.167 | R39: 6 | S39: 11 | T39: 0.545 | U39: 0.441 | V39: 6 | W39: 7 | X39: 0.857 | Y39: 0 | Z39: 4 | AA39: 4 | AB39: 1 | AC39: 2 | AD39: 1 | AE39: 2 | AF39: 3 | AG39: 21 | AH39: 12.9 | AI39: -8
A40: Andrew Wiggins | B40: 35 | C40: 560 | D40: 39 | E40: 44570 | F40: GSW | H40: CLE | I40: W 96-82 | J40: * | K40: 1.4152778 | L40: 3 | M40: 9 | N40: 0.333 | O40: 0 | P40: 3 | Q40: 0 | R40: 3 | S40: 6 | T40: 0.5 | U40: 0.333 | V40: 4 | W40: 4 | X40: 1 | Y40: 0 | Z40: 2 | AA40: 2 | AB40: 1 | AC40: 1 | AD40: 0 | AE40: 0 | AF40: 1 | AG40: 10 | AH40: 6.8 | AI40: 16
...

Sheet davis
A1: Player | B1: Rk | C1: Gcar | D1: Gtm | E1: Date | F1: Team | H1: Opp | I1: Result | J1: GS | K1: MP | L1: FG | M1: FGA | N1: FG% | O1: 3P | P1: 3PA | Q1: 3P% | R1: 2P | S1: 2PA | T1: 2P% | U1: eFG% | V1: FT | W1: FTA | X1: FT% | Y1: ORB | Z1: DRB | AA1: TRB | AB1: AST | AC1: STL | AD1: BLK | AE1: TOV | AF1: PF | AG1: PTS | AH1: GmSc | AI1: +/-
A2: Anthony Davis | B2: 1 | C2: 565 | D2: 1 | E2: 44488 | F2: LAL | H2: GSW | I2: L 114-121 | J2: * | K2: 1.6215278 | L2: 15 | M2: 26 | N2: 0.577 | O2: 1 | P2: 5 | Q2: 0.2 | R2: 14 | S2: 21 | T2: 0.667 | U2: 0.596 | V2: 2 | W2: 7 | X2: 0.286 | Y2: 2 | Z2: 9 | AA2: 11 | AB2: 2 | AC2: 1 | AD2: 2 | AE2: 0 | AF2: 0 | AG2: 33 | AH2: 26.7 | AI2: -2
A3: Anthony Davis | B3: 2 | C3: 566 | D3: 2 | E3: 44491 | F3: LAL | H3: PHO | I3: L 105-115 | J3: * | K3: 1.5895833 | L3: 6 | M3: 18 | N3: 0.333 | O3: 0 | P3: 1 | Q3: 0 | R3: 6 | S3: 17 | T3: 0.353 | U3: 0.333 | V3: 10 | W3: 11 | X3: 0.909 | Y3: 5 | Z3: 9 | AA3: 14 | AB3: 3 | AC3: 1 | AD3: 2 | AE3: 2 | AF3: 3 | AG3: 22 | AH3: 18.9 | AI3: -6
A4: Anthony Davis | B4: 3 | C4: 567 | D4: 3 | E4: 44493 | F4: LAL | H4: MEM | I4: W 121-118 | J4: * | K4: 1.4041667 | L4: 8 | M4: 15 | N4: 0.533 | O4: 1 | P4: 3 | Q4: 0.333 | R4: 7 | S4: 12 | T4: 0.583 | U4: 0.567 | V4: 5 | W4: 7 | X4: 0.714 | Y4: 3 | Z4: 5 | AA4: 8 | AB4: 2 | AC4: 0 | AD4: 4 | AE4: 3 | AF4: 1 | AG4: 22 | AH4: 18.3 | AI4: -5
A5: Anthony Davis | B5: 4 | C5: 568 | D5: 4 | E5: 44495 | F5: LAL | G5: @ | H5: SAS | I5: W 125-121 (OT) | J5: * | K5: 1.7659722 | L5: 15 | M5: 31 | N5: 0.484 | O5: 0 | P5: 4 | Q5: 0 | R5: 15 | S5: 27 | T5: 0.556 | U5: 0.484 | V5: 5 | W5: 6 | X5: 0.833 | Y5: 7 | Z5: 10 | AA5: 17 | AB5: 4 | AC5: 0 | AD5: 4 | AE5: 2 | AF5: 2 | AG5: 35 | AH5: 29.6 | AI5: 3
A6: Anthony Davis | B6: 5 | C6: 569 | D6: 5 | E6: 44496 | F6: LAL | G6: @ | H6: OKC | I6: L 115-123 | J6: * | K6: 1.5236111 | L6: 12 | M6: 22 | N6: 0.545 | O6: 0 | P6: 1 | Q6: 0 | R6: 12 | S6: 21 | T6: 0.571 | U6: 0.545 | V6: 6 | W6: 7 | X6: 0.857 | Y6: 4 | Z6: 4 | AA6: 8 | AB6: 2 | AC6: 1 | AD6: 0 | AE6: 2 | AF6: 1 | AG6: 30 | AH6: 23 | AI6: -7
A7: Anthony Davis | B7: 6 | C7: 570 | D7: 6 | E7: 44498 | F7: LAL | H7: CLE | I7: W 113-101 | J7: * | K7: 1.29375 | L7: 7 | M7: 14 | N7: 0.5 | O7: 1 | P7: 2 | Q7: 0.5 | R7: 6 | S7: 12 | T7: 0.5 | U7: 0.536 | V7: 0 | W7: 0 | Y7: 2 | Z7: 7 | AA7: 9 | AB7: 3 | AC7: 1 | AD7: 3 | AE7: 2 | AF7: 3 | AG7: 15 | AH7: 13.5 | AI7: 11
A8: Anthony Davis | B8: 7 | C8: 571 | D8: 7 | E8: 44500 | F8: LAL | H8: HOU | I8: W 95-85 | J8: * | K8: 1.3576389 | L8: 7 | M8: 17 | N8: 0.412 | O8: 0 | P8: 1 | Q8: 0 | R8: 7 | S8: 16 | T8: 0.438 | U8: 0.412 | V8: 2 | W8: 2 | X8: 1 | Y8: 6 | Z8: 7 | AA8: 13 | AB8: 2 | AC8: 1 | AD8: 1 | AE8: 3 | AF8: 3 | AG8: 16 | AH8: 12.1 | AI8: 6
A9: Anthony Davis | B9: 8 | C9: 572 | D9: 8 | E9: 44502 | F9: LAL | H9: HOU | I9: W 119-117 | J9: * | K9: 1.3347222 | L9: 11 | M9: 18 | N9: 0.611 | O9: 0 | P9: 3 | Q9: 0 | R9: 11 | S9: 15 | T9: 0.733 | U9: 0.611 | V9: 5 | W9: 8 | X9: 0.625 | Y9: 1 | Z9: 8 | AA9: 9 | AB9: 3 | AC9: 3 | AD9: 3 | AE9: 4 | AF9: 2 | AG9: 27 | AH9: 23.1 | AI9: -1
A10: Anthony Davis | B10: 9 | C10: 573 | D10: 9 | E10: 44504 | F10: LAL | H10: OKC | I10: L 104-107 | J10: * | K10: 1.5881944 | L10: 11 | M10: 20 | N10: 0.55 | O10: 0 | P10: 1 | Q10: 0 | R10: 11 | S10: 19 | T10: 0.579 | U10: 0.55 | V10: 7 | W10: 9 | X10: 0.778 | Y10: 6 | Z10: 12 | AA10: 18 | AB10: 5 | AC10: 1 | AD10: 2 | AE10: 3 | AF10: 4 | AG10: 29 | AH10: 27.7 | AI10: -14
A11: Anthony Davis | B11: 10 | C11: 574 | D11: 10 | E11: 44506 | F11: LAL | G11: @ | H11: POR | I11: L 90-105 | J11: * | K11: 0.29791667 | L11: 1 | M11: 5 | N11: 0.2 | O11: 0 | P11: 0 | R11: 1 | S11: 5 | T11: 0.2 | U11: 0.2 | V11: 0 | W11: 0 | Y11: 3 | Z11: 0 | AA11: 3 | AB11: 0 | AC11: 0 | AD11: 0 | AE11: 0 | AF11: 1 | AG11: 2 | AH11: 0.6 | AI11: -11
A12: Anthony Davis | B12: 11 | C12: 575 | D12: 11 | E12: 44508 | F12: LAL | H12: CHO | I12: W 126-123 (OT) | J12: * | K12: 1.8159722 | L12: 13 | M12: 25 | N12: 0.52 | O12: 0 | P12: 3 | Q12: 0 | R12: 13 | S12: 22 | T12: 0.591 | U12: 0.52 | V12: 6 | W12: 8 | X12: 0.75 | Y12: 2 | Z12: 10 | AA12: 12 | AB12: 4 | AC12: 3 | AD12: 5 | AE12: 4 | AF12: 4 | AG12: 32 | AH12: 27 | AI12: -1
A13: Anthony Davis | B13: 12 | C13: 576 | D13: 12 | E13: 44510 | F13: LAL | H13: MIA | I13: W 120-117 (OT) | J13: * | K13: 1.8555556 | L13: 10 | M13: 23 | N13: 0.435 | O13: 1 | P13: 2 | Q13: 0.5 | R13: 9 | S13: 21 | T13: 0.429 | U13: 0.457 | V13: 3 | W13: 4 | X13: 0.75 | Y13: 5 | Z13: 8 | AA13: 13 | AB13: 4 | AC13: 1 | AD13: 1 | AE13: 4 | AF13: 3 | AG13: 24 | AH13: 16.7 | AI13: -4
A14: Anthony Davis | B14: 13 | C14: 577 | D14: 13 | E14: 44512 | F14: LAL | H14: MIN | I14: L 83-107 | J14: * | K14: 1.2902778 | L14: 7 | M14: 13 | N14: 0.538 | O14: 0 | P14: 1 | Q14: 0 | R14: 7 | S14: 12 | T14: 0.583 | U14: 0.538 | V14: 8 | W14: 10 | X14: 0.8 | Y14: 2 | Z14: 6 | AA14: 8 | AB14: 2 | AC14: 3 | AD14: 3 | AE14: 2 | AF14: 4 | AG14: 22 | AH14: 21 | AI14: -16
A15: Anthony Davis | B15: 14 | C15: 578 | D15: 14 | E15: 44514 | F15: LAL | H15: SAS | I15: W 114-106 | J15: * | K15: 1.6527778 | L15: 14 | M15: 24 | N15: 0.583 | O15: 2 | P15: 3 | Q15: 0.667 | R15: 12 | S15: 21 | T15: 0.571 | U15: 0.625 | V15: 4 | W15: 5 | X15: 0.8 | Y15: 5 | Z15: 10 | AA15: 15 | AB15: 6 | AC15: 1 | AD15: 1 | AE15: 1 | AF15: 0 | AG15: 34 | AH15: 33.8 | AI15: 0
A16: Anthony Davis | B16: 15 | C16: 579 | D16: 15 | E16: 44515 | F16: LAL | H16: CHI | I16: L 103-121 | J16: * | K16: 1.1659722 | L16: 6 | M16: 9 | N16: 0.667 | O16: 0 | P16: 0 | R16: 6 | S16: 9 | T16: 0.667 | U16: 0.667 | V16: 8 | W16: 9 | X16: 0.889 | Y16: 1 | Z16: 5 | AA16: 6 | AB16: 1 | AC16: 1 | AD16: 0 | AE16: 4 | AF16: 1 | AG16: 20 | AH16: 15.2 | AI16: -22
A17: Anthony Davis | B17: 16 | C17: 580 | D17: 16 | E17: 44517 | F17: LAL | G17: @ | H17: MIL | I17: L 102-109 | J17: * | K17: 1.5416667 | L17: 9 | M17: 15 | N17: 0.6 | O17: 0 | P17: 1 | Q17: 0 | R17: 9 | S17: 14 | T17: 0.643 | U17: 0.6 | V17: 0 | W17: 0 | Y17: 2 | Z17: 7 | AA17: 9 | AB17: 4 | AC17: 0 | AD17: 2 | AE17: 1 | AF17: 4 | AG17: 18 | AH17: 16.2 | AI17: 5
A18: Anthony Davis | B18: 17 | C18: 581 | D18: 17 | E18: 44519 | F18: LAL | G18: @ | H18: BOS | I18: L 108-130 | J18: * | K18: 1.525 | L18: 12 | M18: 21 | N18: 0.571 | O18: 0 | P18: 3 | Q18: 0 | R18: 12 | S18: 18 | T18: 0.667 | U18: 0.571 | V18: 7 | W18: 9 | X18: 0.778 | Y18: 1 | Z18: 5 | AA18: 6 | AB18: 2 | AC18: 0 | AD18: 3 | AE18: 1 | AF18: 2 | AG18: 31 | AH18: 24.2 | AI18: -14
A19: Anthony Davis | B19: 18 | C19: 582 | D19: 18 | E19: 44521 | F19: LAL | G19: @ | H19: DET | I19: W 121-116 | J19: * | K19: 1.6513889 | L19: 11 | M19: 19 | N19: 0.579 | O19: 0 | P19: 1 | Q19: 0 | R19: 11 | S19: 18 | T19: 0.611 | U19: 0.579 | V19: 8 | W19: 10 | X19: 0.8 | Y19: 1 | Z19: 9 | AA19: 10 | AB19: 6 | AC19: 4 | AD19: 5 | AE19: 2 | AF19: 4 | AG19: 30 | AH19: 31.8 | AI19: 5
A20: Anthony Davis | B20: 19 | C20: 583 | D20: 19 | E20: 44523 | F20: LAL | G20: @ | H20: NYK | I20: L 100-106 | J20: * | K20: 1.4152778 | L20: 7 | M20: 17 | N20: 0.412 | O20: 1 | P20: 2 | Q20: 0.5 | R20: 6 | S20: 15 | T20: 0.4 | U20: 0.441 | V20: 5 | W20: 11 | X20: 0.455 | Y20: 3 | Z20: 3 | AA20: 6 | AB20: 3 | AC20: 0 | AD20: 0 | AE20: 0 | AF20: 1 | AG20: 20 | AH20: 13.2 | AI20: 8
A21: Anthony Davis | B21: 19 | D21: 20 | E21: 44524 | F21: LAL | G21: @ | H21: IND | I21: W 124-116 (OT) | J21: Did Not Dress | K21: Did Not Dress | L21: Did Not Dress | M21: Did Not Dress | N21: Did Not Dress | O21: Did Not Dress | P21: Did Not Dress | Q21: Did Not Dress | R21: Did Not Dress | S21: Did Not Dress | T21: Did Not Dress | U21: Did Not Dress | V21: Did Not Dress | W21: Did Not Dress | X21: Did Not Dress | Y21: Did Not Dress | Z21: Did Not Dress | AA21: Did Not Dress | AB21: Did Not Dress | AC21: Did Not Dress | AD21: Did Not Dress | AE21: Did Not Dress | AF21: Did Not Dress | AG21: Did Not Dress | AH21: Did Not Dress | AI21: Did Not Dress
A22: Anthony Davis | B22: 20 | C22: 584 | D22: 21 | E22: 44526 | F22: LAL | H22: SAC | I22: L 137-141 (3OT) | J22: * | K22: 2.025 | L22: 9 | M22: 22 | N22: 0.409 | O22: 0 | P22: 5 | Q22: 0 | R22: 9 | S22: 17 | T22: 0.529 | U22: 0.409 | V22: 5 | W22: 8 | X22: 0.625 | Y22: 1 | Z22: 7 | AA22: 8 | AB22: 4 | AC22: 3 | AD22: 4 | AE22: 2 | AF22: 5 | AG22: 23 | AH22: 17.4 | AI22: -16
A23: Anthony Davis | B23: 21 | C23: 585 | D23: 22 | E23: 44528 | F23: LAL | H23: DET | I23: W 110-106 | J23: * | K23: 1.5701389 | L23: 10 | M23: 15 | N23: 0.667 | O23: 2 | P23: 2 | Q23: 1 | R23: 8 | S23: 13 | T23: 0.615 | U23: 0.733 | V23: 2 | W23: 3 | X23: 0.667 | Y23: 0 | Z23: 10 | AA23: 10 | AB23: 2 | AC23: 2 | AD23: 3 | AE23: 1 | AF23: 1 | AG23: 24 | AH23: 24.2 | AI23: 4
A24: Anthony Davis | B24: 22 | C24: 586 | D24: 23 | E24: 44530 | F24: LAL | G24: @ | H24: SAC | I24: W 117-92 | J24: * | K24: 1.4548611 | L24: 12 | M24: 22 | N24: 0.545 | O24: 0 | P24: 2 | Q24: 0 | R24: 12 | S24: 20 | T24: 0.6 | U24: 0.545 | V24: 1 | W24: 2 | X24: 0.5 | Y24: 2 | Z24: 5 | AA24: 7 | AB24: 3 | AC24: 2 | AD24: 2 | AE24: 1 | AF24: 2 | AG24: 25 | AH24: 20.6 | AI24: 10
A25: Anthony Davis | B25: 23 | C25: 587 | D25: 24 | E25: 44533 | F25: LAL | H25: LAC | I25: L 115-119 | J25: * | K25: 1.5125 | L25: 10 | M25: 15 | N25: 0.667 | O25: 0 | P25: 2 | Q25: 0 | R25: 10 | S25: 13 | T25: 0.769 | U25: 0.667 | V25: 7 | W25: 11 | X25: 0.636 | Y25: 5 | Z25: 5 | AA25: 10 | AB25: 4 | AC25: 0 | AD25: 1 | AE25: 2 | AF25: 2 | AG25: 27 | AH25: 24.6 | AI25: -9
A26: Anthony Davis | B26: 24 | C26: 588 | D26: 25 | E26: 44537 | F26: LAL | H26: BOS | I26: W 117-102 | J26: * | K26: 1.4784722 | L26: 7 | M26: 13 | N26: 0.538 | O26: 0 | P26: 0 | R26: 7 | S26: 13 | T26: 0.538 | U26: 0.538 | V26: 3 | W26: 4 | X26: 0.75 | Y26: 4 | Z26: 12 | AA26: 16 | AB26: 3 | AC26: 2 | AD26: 2 | AE26: 3 | AF26: 3 | AG26: 17 | AH26: 18 | AI26: 17
A27: Anthony Davis | B27: 25 | C27: 589 | D27: 26 | E27: 44539 | F27: LAL | G27: @ | H27: MEM | I27: L 95-108 | J27: * | K27: 1.5888889 | L27: 9 | M27: 18 | N27: 0.5 | O27: 1 | P27: 4 | Q27: 0.25 | R27: 8 | S27: 14 | T27: 0.571 | U27: 0.528 | V27: 3 | W27: 4 | X27: 0.75 | Y27: 1 | Z27: 7 | AA27: 8 | AB27: 1 | AC27: 1 | AD27: 1 | AE27: 2 | AF27: 1 | AG27: 22 | AH27: 15.4 | AI27: -2
A28: Anthony Davis | B28: 25 | D28: 27 | E28: 44540 | F28: LAL | G28: @ | H28: OKC | I28: W 116-95 | J28: Did Not Dress | K28: Did Not Dress | L28: Did Not Dress | M28: Did Not Dress | N28: Did Not Dress | O28: Did Not Dress | P28: Did Not Dress | Q28: Did Not Dress | R28: Did Not Dress | S28: Did Not Dress | T28: Did Not Dress | U28: Did Not Dress | V28: Did Not Dress | W28: Did Not Dress | X28: Did Not Dress | Y28: Did Not Dress | Z28: Did Not Dress | AA28: Did Not Dress | AB28: Did Not Dress | AC28: Did Not Dress | AD28: Did Not Dress | AE28: Did Not Dress | AF28: Did Not Dress | AG28: Did Not Dress | AH28: Did Not Dress | AI28: Did Not Dress
A29: Anthony Davis | B29: 25 | D29: 28 | E29: 44542 | F29: LAL | H29: ORL | I29: W 106-94 | J29: Did Not Dress | K29: Did Not Dress | L29: Did Not Dress | M29: Did Not Dress | N29: Did Not Dress | O29: Did Not Dress | P29: Did Not Dress | Q29: Did Not Dress | R29: Did Not Dress | S29: Did Not Dress | T29: Did Not Dress | U29: Did Not Dress | V29: Did Not Dress | W29: Did Not Dress | X29: Did Not Dress | Y29: Did Not Dress | Z29: Did Not Dress | AA29: Did Not Dress | AB29: Did Not Dress | AC29: Did Not Dress | AD29: Did Not Dress | AE29: Did Not Dress | AF29: Did Not Dress | AG29: Did Not Dress | AH29: Did Not Dress | AI29: Did Not Dress
A30: Anthony Davis | B30: 26 | C30: 590 | D30: 29 | E30: 44545 | F30: LAL | G30: @ | H30: DAL | I30: W 107-104 (OT) | J30: * | K30: 1.6409722 | L30: 8 | M30: 18 | N30: 0.444 | O30: 0 | P30: 3 | Q30: 0 | R30: 8 | S30: 15 | T30: 0.533 | U30: 0.444 | V30: 4 | W30: 5 | X30: 0.8 | Y30: 0 | Z30: 12 | AA30: 12 | AB30: 2 | AC30: 0 | AD30: 0 | AE30: 6 | AF30: 4 | AG30: 20 | AH30: 7.6 | AI30: 21
A31: Anthony Davis | B31: 27 | C31: 591 | D31: 30 | E31: 44547 | F31: LAL | G31: @ | H31: MIN | I31: L 92-110 | J31: * | K31: 0.83680556 | L31: 4 | M31: 7 | N31: 0.571 | O31: 0 | P31: 1 | Q31: 0 | R31: 4 | S31: 6 | T31: 0.667 | U31: 0.571 | V31: 1 | W31: 1 | X31: 1 | Y31: 0 | Z31: 1 | AA31: 1 | AB31: 0 | AC31: 0 | AD31: 1 | AE31: 3 | AF31: 2 | AG31: 9 | AH31: 2.9 | AI31: -8
A32: Anthony Davis | B32: 27 | D32: 31 | E32: 44549 | F32: LAL | G32: @ | H32: CHI | I32: L 110-115 | J32: Did Not Dress | K32: Did Not Dress | L32: Did Not Dress | M32: Did Not Dress | N32: Did Not Dress | O32: Did Not Dress | P32: Did Not Dress | Q32: Did Not Dress | R32: Did Not Dress | S32: Did Not Dress | T32: Did Not Dress | U32: Did Not Dress | V32: Did Not Dress | W32: Did Not Dress | X32: Did Not Dress | Y32: Did Not Dress | Z32: Did Not Dress | AA32: Did Not Dress | AB32: Did Not Dress | AC32: Did Not Dress | AD32: Did Not Dress | AE32: Did Not Dress | AF32: Did Not Dress | AG32: Did Not Dress | AH32: Did Not Dress | AI32: Did Not Dress
A33: Anthony Davis | B33: 27 | D33: 32 | E33: 44551 | F33: LAL | H33: PHO | I33: L 90-108 | J33: Inactive | K33: Inactive | L33: Inactive | M33: Inactive | N33: Inactive | O33: Inactive | P33: Inactive | Q33: Inactive | R33: Inactive | S33: Inactive | T33: Inactive | U33: Inactive | V33: Inactive | W33: Inactive | X33: Inactive | Y33: Inactive | Z33: Inactive | AA33: Inactive | AB33: Inactive | AC33: Inactive | AD33: Inactive | AE33: Inactive | AF33: Inactive | AG33: Inactive | AH33: Inactive | AI33: Inactive
A34: Anthony Davis | B34: 27 | D34: 33 | E34: 44553 | F34: LAL | H34: SAS | I34: L 110-138 | J34: Inactive | K34: Inactive | L34: Inactive | M34: Inactive | N34: Inactive | O34: Inactive | P34: Inactive | Q34: Inactive | R34: Inactive | S34: Inactive | T34: Inactive | U34: Inactive | V34: Inactive | W34: Inactive | X34: Inactive | Y34: Inactive | Z34: Inactive | AA34: Inactive | AB34: Inactive | AC34: Inactive | AD34: Inactive | AE34: Inactive | AF34: Inactive | AG34: Inactive | AH34: Inactive | AI34: Inactive
A35: Anthony Davis | B35: 27 | D35: 34 | E35: 44555 | F35: LAL | H35: BRK | I35: L 115-122 | J35: Inactive | K35: Inactive | L35: Inactive | M35: Inactive | N35: Inactive | O35: Inactive | P35: Inactive | Q35: Inactive | R35: Inactive | S35: Inactive | T35: Inactive | U35: Inactive | V35: Inactive | W35: Inactive | X35: Inactive | Y35: Inactive | Z35: Inactive | AA35: Inactive | AB35: Inactive | AC35: Inactive | AD35: Inactive | AE35: Inactive | AF35: Inactive | AG35: Inactive | AH35: Inactive | AI35: Inactive
A36: Anthony Davis | B36: 27 | D36: 35 | E36: 44558 | F36: LAL | G36: @ | H36: HOU | I36: W 132-123 | J36: Inactive | K36: Inactive | L36: Inactive | M36: Inactive | N36: Inactive | O36: Inactive | P36: Inactive | Q36: Inactive | R36: Inactive | S36: Inactive | T36: Inactive | U36: Inactive | V36: Inactive | W36: Inactive | X36: Inactive | Y36: Inactive | Z36: Inactive | AA36: Inactive | AB36: Inactive | AC36: Inactive | AD36: Inactive | AE36: Inactive | AF36: Inactive | AG36: Inactive | AH36: Inactive | AI36: Inactive
A37: Anthony Davis | B37: 27 | D37: 36 | E37: 44559 | F37: LAL | G37: @ | H37: MEM | I37: L 99-104 | J37: Inactive | K37: Inactive | L37: Inactive | M37: Inactive | N37: Inactive | O37: Inactive | P37: Inactive | Q37: Inactive | R37: Inactive | S37: Inactive | T37: Inactive | U37: Inactive | V37: Inactive | W37: Inactive | X37: Inactive | Y37: Inactive | Z37: Inactive | AA37: Inactive | AB37: Inactive | AC37: Inactive | AD37: Inactive | AE37: Inactive | AF37: Inactive | AG37: Inactive | AH37: Inactive | AI37: Inactive
A38: Anthony Davis | B38: 27 | D38: 37 | E38: 44561 | F38: LAL | H38: POR | I38: W 139-106 | J38: Inactive | K38: Inactive | L38: Inactive | M38: Inactive | N38: Inactive | O38: Inactive | P38: Inactive | Q38: Inactive | R38: Inactive | S38: Inactive | T38: Inactive | U38: Inactive | V38: Inactive | W38: Inactive | X38: Inactive | Y38: Inactive | Z38: Inactive | AA38: Inactive | AB38: Inactive | AC38: Inactive | AD38: Inactive | AE38: Inactive | AF38: Inactive | AG38: Inactive | AH38: Inactive | AI38: Inactive
A39: Anthony Davis | B39: 27 | D39: 38 | E39: 44563 | F39: LAL | H39: MIN | I39: W 108-103 | J39: Inactive | K39: Inactive | L39: Inactive | M39: Inactive | N39: Inactive | O39: Inactive | P39: Inactive | Q39: Inactive | R39: Inactive | S39: Inactive | T39: Inactive | U39: Inactive | V39: Inactive | W39: Inactive | X39: Inactive | Y39: Inactive | Z39: Inactive | AA39: Inactive | AB39: Inactive | AC39: Inactive | AD39: Inactive | AE39: Inactive | AF39: Inactive | AG39: Inactive | AH39: Inactive | AI39: Inactive
A40: Anthony Davis | B40: 27 | D40: 39 | E40: 44565 | F40: LAL | H40: SAC | I40: W 122-114 | J40: Inactive | K40: Inactive | L40: Inactive | M40: Inactive | N40: Inactive | O40: Inactive | P40: Inactive | Q40: Inactive | R40: Inactive | S40: Inactive | T40: Inactive | U40: Inactive | V40: Inactive | W40: Inactive | X40: Inactive | Y40: Inactive | Z40: Inactive | AA40: Inactive | AB40: Inactive | AC40: Inactive | AD40: Inactive | AE40: Inactive | AF40: Inactive | AG40: Inactive | AH40: Inactive | AI40: Inactive
...

Sheet cp3
A1: Player | B1: Rk | C1: Gcar | D1: Gtm | E1: Date | F1: Team | H1: Opp | I1: Result | J1: GS | K1: MP | L1: FG | M1: FGA | N1: FG% | O1: 3P | P1: 3PA | Q1: 3P% | R1: 2P | S1: 2PA | T1: 2P% | U1: eFG% | V1: FT | W1: FTA | X1: FT% | Y1: ORB | Z1: DRB | AA1: TRB | AB1: AST | AC1: STL | AD1: BLK | AE1: TOV | AF1: PF | AG1: PTS | AH1: GmSc | AI1: +/-
A2: Chris Paul | B2: 1 | C2: 1091 | D2: 1 | E2: 44489 | F2: PHO | H2: DEN | I2: L 98-110 | J2: * | K2: 1.4006944 | L2: 6 | M2: 11 | N2: 0.545 | O2: 2 | P2: 4 | Q2: 0.5 | R2: 4 | S2: 7 | T2: 0.571 | U2: 0.636 | V2: 1 | W2: 2 | X2: 0.5 | Y2: 2 | Z2: 2 | AA2: 4 | AB2: 10 | AC2: 2 | AD2: 1 | AE2: 3 | AF2: 3 | AG2: 15 | AH2: 16.8 | AI2: -23
A3: Chris Paul | B3: 2 | C3: 1092 | D3: 2 | E3: 44491 | F3: PHO | G3: @ | H3: LAL | I3: W 115-105 | J3: * | K3: 1.2180556 | L3: 6 | M3: 12 | N3: 0.5 | O3: 1 | P3: 4 | Q3: 0.25 | R3: 5 | S3: 8 | T3: 0.625 | U3: 0.542 | V3: 10 | W3: 10 | X3: 1 | Y3: 0 | Z3: 5 | AA3: 5 | AB3: 14 | AC3: 2 | AD3: 0 | AE3: 5 | AF3: 3 | AG3: 23 | AH3: 24.1 | AI3: 6
A4: Chris Paul | B4: 3 | C4: 1093 | D4: 3 | E4: 44492 | F4: PHO | G4: @ | H4: POR | I4: L 105-134 | J4: * | K4: 1.0625 | L4: 2 | M4: 5 | N4: 0.4 | O4: 0 | P4: 2 | Q4: 0 | R4: 2 | S4: 3 | T4: 0.667 | U4: 0.4 | V4: 0 | W4: 0 | Y4: 0 | Z4: 2 | AA4: 2 | AB4: 11 | AC4: 1 | AD4: 0 | AE4: 1 | AF4: 0 | AG4: 4 | AH4: 9.6 | AI4: -29
A5: Chris Paul | B5: 4 | C5: 1094 | D5: 4 | E5: 44496 | F5: PHO | H5: SAC | I5: L 107-110 | J5: * | K5: 1.2388889 | L5: 1 | M5: 10 | N5: 0.1 | O5: 0 | P5: 0 | R5: 1 | S5: 10 | T5: 0.1 | U5: 0.1 | V5: 4 | W5: 4 | X5: 1 | Y5: 3 | Z5: 3 | AA5: 6 | AB5: 8 | AC5: 2 | AD5: 0 | AE5: 1 | AF5: 2 | AG5: 6 | AH5: 8.2 | AI5: -10
A6: Chris Paul | B6: 5 | C6: 1095 | D6: 5 | E6: 44499 | F6: PHO | H6: CLE | I6: W 101-92 | J6: * | K6: 1.5305556 | L6: 6 | M6: 10 | N6: 0.6 | O6: 2 | P6: 2 | Q6: 1 | R6: 4 | S6: 8 | T6: 0.5 | U6: 0.7 | V6: 2 | W6: 6 | X6: 0.333 | Y6: 0 | Z6: 2 | AA6: 2 | AB6: 10 | AC6: 4 | AD6: 0 | AE6: 2 | AF6: 2 | AG6: 16 | AH6: 18.6 | AI6: 18
A7: Chris Paul | B7: 6 | C7: 1096 | D7: 6 | E7: 44502 | F7: PHO | H7: NOP | I7: W 112-100 | J7: * | K7: 1.5027778 | L7: 6 | M7: 8 | N7: 0.75 | O7: 0 | P7: 0 | R7: 6 | S7: 8 | T7: 0.75 | U7: 0.75 | V7: 2 | W7: 2 | X7: 1 | Y7: 0 | Z7: 7 | AA7: 7 | AB7: 18 | AC7: 1 | AD7: 1 | AE7: 4 | AF7: 3 | AG7: 14 | AH7: 22 | AI7: 16
A8: Chris Paul | B8: 7 | C8: 1097 | D8: 7 | E8: 44504 | F8: PHO | H8: HOU | I8: W 123-111 | J8: * | K8: 1.4326389 | L8: 3 | M8: 10 | N8: 0.3 | O8: 1 | P8: 5 | Q8: 0.2 | R8: 2 | S8: 5 | T8: 0.4 | U8: 0.35 | V8: 2 | W8: 2 | X8: 1 | Y8: 0 | Z8: 5 | AA8: 5 | AB8: 13 | AC8: 5 | AD8: 2 | AE8: 2 | AF8: 3 | AG8: 9 | AH8: 17 | AI8: 12
A9: Chris Paul | B9: 8 | C9: 1098 | D9: 8 | E9: 44506 | F9: PHO | H9: ATL | I9: W 121-117 | J9: * | K9: 1.4770833 | L9: 5 | M9: 8 | N9: 0.625 | O9: 1 | P9: 2 | Q9: 0.5 | R9: 4 | S9: 6 | T9: 0.667 | U9: 0.688 | V9: 5 | W9: 6 | X9: 0.833 | Y9: 0 | Z9: 6 | AA9: 6 | AB9: 13 | AC9: 1 | AD9: 1 | AE9: 2 | AF9: 1 | AG9: 16 | AH9: 22.2 | AI9: 26
A10: Chris Paul | B10: 9 | C10: 1099 | D10: 9 | E10: 44508 | F10: PHO | G10: @ | H10: SAC | I10: W 109-104 | J10: * | K10: 1.0763889 | L10: 6 | M10: 12 | N10: 0.5 | O10: 2 | P10: 3 | Q10: 0.667 | R10: 4 | S10: 9 | T10: 0.444 | U10: 0.583 | V10: 2 | W10: 2 | X10: 1 | Y10: 0 | Z10: 3 | AA10: 3 | AB10: 5 | AC10: 3 | AD10: 0 | AE10: 2 | AF10: 1 | AG10: 16 | AH10: 15 | AI10: 7
A11: Chris Paul | B11: 10 | C11: 1100 | D11: 10 | E11: 44510 | F11: PHO | H11: POR | I11: W 119-109 | J11: * | K11: 1.5270833 | L11: 9 | M11: 16 | N11: 0.563 | O11: 1 | P11: 3 | Q11: 0.333 | R11: 8 | S11: 13 | T11: 0.615 | U11: 0.594 | V11: 2 | W11: 3 | X11: 0.667 | Y11: 1 | Z11: 3 | AA11: 4 | AB11: 7 | AC11: 0 | AD11: 1 | AE11: 2 | AF11: 2 | AG11: 21 | AH11: 17.4 | AI11: 4
A12: Chris Paul | B12: 11 | C12: 1101 | D12: 11 | E12: 44512 | F12: PHO | G12: @ | H12: MEM | I12: W 119-94 | J12: * | K12: 1.1520833 | L12: 6 | M12: 12 | N12: 0.5 | O12: 0 | P12: 2 | Q12: 0 | R12: 6 | S12: 10 | T12: 0.6 | U12: 0.5 | V12: 3 | W12: 3 | X12: 1 | Y12: 0 | Z12: 4 | AA12: 4 | AB12: 12 | AC12: 5 | AD12: 0 | AE12: 2 | AF12: 2 | AG12: 15 | AH12: 20.8 | AI12: 20
A13: Chris Paul | B13: 12 | C13: 1102 | D13: 12 | E13: 44514 | F13: PHO | G13: @ | H13: HOU | I13: W 115-89 | J13: * | K13: 1.2291667 | L13: 6 | M13: 11 | N13: 0.545 | O13: 2 | P13: 5 | Q13: 0.4 | R13: 4 | S13: 6 | T13: 0.667 | U13: 0.636 | V13: 1 | W13: 1 | X13: 1 | Y13: 0 | Z13: 3 | AA13: 3 | AB13: 4 | AC13: 7 | AD13: 0 | AE13: 2 | AF13: 2 | AG13: 15 | AH13: 17.6 | AI13: 25
A14: Chris Paul | B14: 13 | C14: 1103 | D14: 13 | E14: 44515 | F14: PHO | G14: @ | H14: MIN | I14: W 99-96 | J14: * | K14: 1.4 | L14: 6 | M14: 14 | N14: 0.429 | O14: 2 | P14: 5 | Q14: 0.4 | R14: 4 | S14: 9 | T14: 0.444 | U14: 0.5 | V14: 7 | W14: 7 | X14: 1 | Y14: 0 | Z14: 3 | AA14: 3 | AB14: 8 | AC14: 1 | AD14: 0 | AE14: 3 | AF14: 1 | AG14: 21 | AH14: 17.7 | AI14: -13
A15: Chris Paul | B15: 14 | C15: 1104 | D15: 14 | E15: 44517 | F15: PHO | H15: DAL | I15: W 105-98 | J15: * | K15: 1.5347222 | L15: 2 | M15: 12 | N15: 0.167 | O15: 0 | P15: 6 | Q15: 0 | R15: 2 | S15: 6 | T15: 0.333 | U15: 0.167 | V15: 3 | W15: 4 | X15: 0.75 | Y15: 0 | Z15: 4 | AA15: 4 | AB15: 14 | AC15: 0 | AD15: 0 | AE15: 0 | AF15: 2 | AG15: 7 | AH15: 9.2 | AI15: 1
A16: Chris Paul | B16: 15 | C16: 1105 | D16: 15 | E16: 44519 | F16: PHO | H16: DAL | I16: W 112-104 | J16: * | K16: 1.3972222 | L16: 7 | M16: 14 | N16: 0.5 | O16: 2 | P16: 4 | Q16: 0.5 | R16: 5 | S16: 10 | T16: 0.5 | U16: 0.571 | V16: 2 | W16: 2 | X16: 1 | Y16: 0 | Z16: 5 | AA16: 5 | AB16: 14 | AC16: 3 | AD16: 0 | AE16: 5 | AF16: 2 | AG16: 18 | AH16: 19.5 | AI16: 10
A17: Chris Paul | B17: 16 | C17: 1106 | D17: 16 | E17: 44521 | F17: PHO | H17: DEN | I17: W 126-97 | J17: * | K17: 1.0152778 | L17: 2 | M17: 4 | N17: 0.5 | O17: 0 | P17: 2 | Q17: 0 | R17: 2 | S17: 2 | T17: 1 | U17: 0.5 | V17: 5 | W17: 5 | X17: 1 | Y17: 0 | Z17: 3 | AA17: 3 | AB17: 10 | AC17: 0 | AD17: 0 | AE17: 0 | AF17: 3 | AG17: 9 | AH17: 13.7 | AI17: 7
A18: Chris Paul | B18: 17 | C18: 1107 | D18: 17 | E18: 44522 | F18: PHO | G18: @ | H18: SAS | I18: W 115-111 | J18: * | K18: 1.275 | L18: 6 | M18: 12 | N18: 0.5 | O18: 0 | P18: 2 | Q18: 0 | R18: 6 | S18: 10 | T18: 0.6 | U18: 0.5 | V18: 0 | W18: 0 | Y18: 0 | Z18: 2 | AA18: 2 | AB18: 4 | AC18: 1 | AD18: 0 | AE18: 3 | AF18: 1 | AG18: 12 | AH18: 7 | AI18: -14
A19: Chris Paul | B19: 18 | C19: 1108 | D19: 18 | E19: 44524 | F19: PHO | G19: @ | H19: CLE | I19: W 120-115 | J19: * | K19: 1.3451389 | L19: 4 | M19: 8 | N19: 0.5 | O19: 2 | P19: 3 | Q19: 0.667 | R19: 2 | S19: 5 | T19: 0.4 | U19: 0.625 | V19: 7 | W19: 8 | X19: 0.875 | Y19: 0 | Z19: 2 | AA19: 2 | AB19: 12 | AC19: 0 | AD19: 0 | AE19: 3 | AF19: 3 | AG19: 17 | AH19: 17.4 | AI19: 23
A20: Chris Paul | B20: 19 | C20: 1109 | D20: 19 | E20: 44526 | F20: PHO | G20: @ | H20: NYK | I20: W 118-97 | J20: * | K20: 1.2597222 | L20: 3 | M20: 6 | N20: 0.5 | O20: 1 | P20: 1 | Q20: 1 | R20: 2 | S20: 5 | T20: 0.4 | U20: 0.583 | V20: 7 | W20: 9 | X20: 0.778 | Y20: 0 | Z20: 4 | AA20: 4 | AB20: 10 | AC20: 1 | AD20: 0 | AE20: 2 | AF20: 1 | AG20: 14 | AH20: 17 | AI20: 7
A21: Chris Paul | B21: 20 | C21: 1110 | D21: 20 | E21: 44527 | F21: PHO | G21: @ | H21: BRK | I21: W 113-107 | J21: * | K21: 1.4979167 | L21: 9 | M21: 19 | N21: 0.474 | O21: 3 | P21: 8 | Q21: 0.375 | R21: 6 | S21: 11 | T21: 0.545 | U21: 0.553 | V21: 1 | W21: 2 | X21: 0.5 | Y21: 0 | Z21: 8 | AA21: 8 | AB21: 5 | AC21: 0 | AD21: 0 | AE21: 2 | AF21: 1 | AG21: 22 | AH21: 15.4 | AI21: -1
A22: Chris Paul | B22: 21 | C22: 1111 | D22: 21 | E22: 44530 | F22: PHO | H22: GSW | I22: W 104-96 | J22: * | K22: 1.6423611 | L22: 7 | M22: 13 | N22: 0.538 | O22: 1 | P22: 3 | Q22: 0.333 | R22: 6 | S22: 10 | T22: 0.6 | U22: 0.577 | V22: 0 | W22: 0 | Y22: 0 | Z22: 6 | AA22: 6 | AB22: 11 | AC22: 5 | AD22: 0 | AE22: 2 | AF22: 3 | AG22: 15 | AH22: 20 | AI22: 21
A23: Chris Paul | B23: 22 | C23: 1112 | D23: 22 | E23: 44532 | F23: PHO | H23: DET | I23: W 114-103 | J23: * | K23: 1.3881944 | L23: 4 | M23: 7 | N23: 0.571 | O23: 0 | P23: 0 | R23: 4 | S23: 7 | T23: 0.571 | U23: 0.571 | V23: 4 | W23: 4 | X23: 1 | Y23: 0 | Z23: 1 | AA23: 1 | AB23: 12 | AC23: 2 | AD23: 0 | AE23: 3 | AF23: 4 | AG23: 12 | AH23: 14.8 | AI23: 2
A24: Chris Paul | B24: 23 | C24: 1113 | D24: 23 | E24: 44533 | F24: PHO | G24: @ | H24: GSW | I24: L 96-118 | J24: * | K24: 1.3486111 | L24: 4 | M24: 8 | N24: 0.5 | O24: 0 | P24: 2 | Q24: 0 | R24: 4 | S24: 6 | T24: 0.667 | U24: 0.5 | V24: 4 | W24: 6 | X24: 0.667 | Y24: 0 | Z24: 3 | AA24: 3 | AB24: 8 | AC24: 1 | AD24: 0 | AE24: 4 | AF24: 0 | AG24: 12 | AH24: 10.7 | AI24: -14
A25: Chris Paul | B25: 24 | C25: 1114 | D25: 24 | E25: 44536 | F25: PHO | H25: SAS | I25: W 108-104 | J25: * | K25: 1.4770833 | L25: 9 | M25: 18 | N25: 0.5 | O25: 2 | P25: 5 | Q25: 0.4 | R25: 7 | S25: 13 | T25: 0.538 | U25: 0.556 | V25: 1 | W25: 3 | X25: 0.333 | Y25: 0 | Z25: 3 | AA25: 3 | AB25: 10 | AC25: 1 | AD25: 1 | AE25: 3 | AF25: 3 | AG25: 21 | AH25: 16.6 | AI25: 4
A26: Chris Paul | B26: 25 | C26: 1115 | D26: 25 | E26: 44540 | F26: PHO | H26: BOS | I26: W 111-90 | J26: * | K26: 1.2381944 | L26: 4 | M26: 9 | N26: 0.444 | O26: 0 | P26: 2 | Q26: 0 | R26: 4 | S26: 7 | T26: 0.571 | U26: 0.444 | V26: 2 | W26: 2 | X26: 1 | Y26: 1 | Z26: 2 | AA26: 3 | AB26: 12 | AC26: 1 | AD26: 2 | AE26: 1 | AF26: 4 | AG26: 10 | AH26: 14.8 | AI26: 20
A27: Chris Paul | B27: 26 | C27: 1116 | D27: 26 | E27: 44543 | F27: PHO | G27: @ | H27: LAC | I27: L 95-111 | J27: * | K27: 1.3875 | L27: 4 | M27: 14 | N27: 0.286 | O27: 0 | P27: 2 | Q27: 0 | R27: 4 | S27: 12 | T27: 0.333 | U27: 0.286 | V27: 1 | W27: 2 | X27: 0.5 | Y27: 0 | Z27: 2 | AA27: 2 | AB27: 8 | AC27: 3 | AD27: 0 | AE27: 2 | AF27: 3 | AG27: 9 | AH27: 6.4 | AI27: -15
A28: Chris Paul | B28: 27 | C28: 1117 | D28: 27 | E28: 44544 | F28: PHO | G28: @ | H28: POR | I28: W 111-107 (OT) | J28: * | K28: 1.7125 | L28: 10 | M28: 19 | N28: 0.526 | O28: 1 | P28: 1 | Q28: 1 | R28: 9 | S28: 18 | T28: 0.5 | U28: 0.553 | V28: 3 | W28: 4 | X28: 0.75 | Y28: 0 | Z28: 8 | AA28: 8 | AB28: 14 | AC28: 3 | AD28: 0 | AE28: 3 | AF28: 4 | AG28: 24 | AH28: 24.9 | AI28: 6
A29: Chris Paul | B29: 28 | C29: 1118 | D29: 28 | E29: 44546 | F29: PHO | H29: WAS | I29: W 118-98 | J29: * | K29: 0.97916667 | L29: 6 | M29: 8 | N29: 0.75 | O29: 0 | P29: 1 | Q29: 0 | R29: 6 | S29: 7 | T29: 0.857 | U29: 0.75 | V29: 0 | W29: 0 | Y29: 0 | Z29: 5 | AA29: 5 | AB29: 6 | AC29: 2 | AD29: 0 | AE29: 3 | AF29: 1 | AG29: 12 | AH29: 13.1 | AI29: 14
A30: Chris Paul | B30: 29 | C30: 1119 | D30: 29 | E30: 44549 | F30: PHO | H30: CHO | I30: W 137-106 | J30: * | K30: 1.0034722 | L30: 6 | M30: 9 | N30: 0.667 | O30: 2 | P30: 4 | Q30: 0.5 | R30: 4 | S30: 5 | T30: 0.8 | U30: 0.778 | V30: 0 | W30: 0 | Y30: 0 | Z30: 2 | AA30: 2 | AB30: 9 | AC30: 1 | AD30: 0 | AE30: 1 | AF30: 2 | AG30: 14 | AH30: 16.2 | AI30: 24
A31: Chris Paul | B31: 30 | C31: 1120 | D31: 30 | E31: 44551 | F31: PHO | G31: @ | H31: LAL | I31: W 108-90 | J31: * | K31: 1.1972222 | L31: 5 | M31: 8 | N31: 0.625 | O31: 0 | P31: 2 | Q31: 0 | R31: 5 | S31: 6 | T31: 0.833 | U31: 0.625 | V31: 1 | W31: 1 | X31: 1 | Y31: 0 | Z31: 3 | AA31: 3 | AB31: 9 | AC31: 1 | AD31: 0 | AE31: 2 | AF31: 2 | AG31: 11 | AH31: 12.8 | AI31: 14
A32: Chris Paul | B32: 31 | C32: 1121 | D32: 31 | E32: 44553 | F32: PHO | H32: OKC | I32: W 113-101 | J32: * | K32: 1.3201389 | L32: 7 | M32: 14 | N32: 0.5 | O32: 1 | P32: 6 | Q32: 0.167 | R32: 6 | S32: 8 | T32: 0.75 | U32: 0.536 | V32: 1 | W32: 2 | X32: 0.5 | Y32: 0 | Z32: 5 | AA32: 5 | AB32: 7 | AC32: 3 | AD32: 0 | AE32: 2 | AF32: 3 | AG32: 16 | AH32: 14.8 | AI32: -2
A33: Chris Paul | B33: 32 | C33: 1122 | D33: 32 | E33: 44555 | F33: PHO | H33: GSW | I33: L 107-116 | J33: * | K33: 1.5645833 | L33: 7 | M33: 14 | N33: 0.5 | O33: 2 | P33: 4 | Q33: 0.5 | R33: 5 | S33: 10 | T33: 0.5 | U33: 0.571 | V33: 5 | W33: 5 | X33: 1 | Y33: 1 | Z33: 5 | AA33: 6 | AB33: 8 | AC33: 0 | AD33: 0 | AE33: 2 | AF33: 2 | AG33: 21 | AH33: 19 | AI33: -5
A34: Chris Paul | B34: 33 | C34: 1123 | D34: 33 | E34: 44557 | F34: PHO | H34: MEM | I34: L 113-114 | J34: * | K34: 1.475 | L34: 4 | M34: 13 | N34: 0.308 | O34: 0 | P34: 3 | Q34: 0 | R34: 4 | S34: 10 | T34: 0.4 | U34: 0.308 | V34: 5 | W34: 5 | X34: 1 | Y34: 0 | Z34: 6 | AA34: 6 | AB34: 13 | AC34: 3 | AD34: 0 | AE34: 3 | AF34: 2 | AG34: 13 | AH34: 15.6 | AI34: -5
